nohup: ignoring input
[2025-07-12 22:01:32] [INFO    ] discord.client: logging in using static token
2025-07-12 22:01:32,489 - discord.client - INFO - logging in using static token
[2025-07-12 22:01:33] [INFO    ] discord.gateway: Shard ID None has connected to Gateway (Session ID: ca3aca3ddae4ec92acb348da34792827).
2025-07-12 22:01:33,359 - discord.gateway - INFO - Shard ID None has connected to Gateway (Session ID: ca3aca3ddae4ec92acb348da34792827).
2025-07-12 22:01:35,405 - __main__ - INFO - Xandeum AI Bot#9241 has connected to Discord!
2025-07-12 22:01:35,405 - __main__ - INFO - Bot is in 1 guild(s)
[2025-07-12 22:02:10] [ERROR   ] discord.client: Ignoring exception in on_message
Traceback (most recent call last):
  File "/usr/local/lib/python3.10/dist-packages/discord/client.py", line 481, in _run_event
    await coro(*args, **kwargs)
  File "/root/xandeum_ai_bot/bot.py", line 68, in on_message
    if ai_handler.should_respond_to_message(message.content):
AttributeError: 'AIHandler' object has no attribute 'should_respond_to_message'
2025-07-12 22:02:10,400 - discord.client - ERROR - Ignoring exception in on_message
Traceback (most recent call last):
  File "/usr/local/lib/python3.10/dist-packages/discord/client.py", line 481, in _run_event
    await coro(*args, **kwargs)
  File "/root/xandeum_ai_bot/bot.py", line 68, in on_message
    if ai_handler.should_respond_to_message(message.content):
AttributeError: 'AIHandler' object has no attribute 'should_respond_to_message'
[2025-07-12 22:03:58] [ERROR   ] discord.client: Ignoring exception in on_message
Traceback (most recent call last):
  File "/usr/local/lib/python3.10/dist-packages/discord/client.py", line 481, in _run_event
    await coro(*args, **kwargs)
  File "/root/xandeum_ai_bot/bot.py", line 68, in on_message
    if ai_handler.should_respond_to_message(message.content):
AttributeError: 'AIHandler' object has no attribute 'should_respond_to_message'
2025-07-12 22:03:58,956 - discord.client - ERROR - Ignoring exception in on_message
Traceback (most recent call last):
  File "/usr/local/lib/python3.10/dist-packages/discord/client.py", line 481, in _run_event
    await coro(*args, **kwargs)
  File "/root/xandeum_ai_bot/bot.py", line 68, in on_message
    if ai_handler.should_respond_to_message(message.content):
AttributeError: 'AIHandler' object has no attribute 'should_respond_to_message'
[2025-07-12 22:04:13] [ERROR   ] discord.client: Ignoring exception in on_message
Traceback (most recent call last):
  File "/usr/local/lib/python3.10/dist-packages/discord/client.py", line 481, in _run_event
    await coro(*args, **kwargs)
  File "/root/xandeum_ai_bot/bot.py", line 68, in on_message
    if ai_handler.should_respond_to_message(message.content):
AttributeError: 'AIHandler' object has no attribute 'should_respond_to_message'
2025-07-12 22:04:13,178 - discord.client - ERROR - Ignoring exception in on_message
Traceback (most recent call last):
  File "/usr/local/lib/python3.10/dist-packages/discord/client.py", line 481, in _run_event
    await coro(*args, **kwargs)
  File "/root/xandeum_ai_bot/bot.py", line 68, in on_message
    if ai_handler.should_respond_to_message(message.content):
AttributeError: 'AIHandler' object has no attribute 'should_respond_to_message'
